---

title: JavaScript Promise catch() Method

date: 2025-05-27

---


# JavaScript Promise catch() Method

JavaScript promises provide a powerful abstraction for handling asynchronous operations, but managing errors within these chains can be complex. The `catch()` method offers a specialized way to handle rejections that differs from the general `.then()` method. In this article, we'll explore the nuances of `catch()`, from its basic syntax and error handling capabilities to its behavior within promise chains and its implementation across JavaScript environments. Understanding these aspects is crucial for building robust asynchronous applications that can gracefully manage errors.


## Syntax and Basic Usage

The `catch()` method returns a Promise that remains in the pending state, even if the previous promise is fulfilled, rejected, or still pending. When called on an already resolved promise, it logs the error message but does not call the error handler. This behavior is consistent with the promise prototype's `.catch` method, which always returns a promise, regardless of the original promise's state.

The method internally calls `Promise.prototype.then` on the object upon which it was called, passing `undefined` and the received `onRejected` handler. As noted in the documentation, "the catch method internally calls `obj.then(undefined, onRejected)`, which internally calls `obj.then`."

The `catch()` method can appear anywhere in the promise chain and handles errors of all kinds, including explicit rejections and accidental errors in handlers above. For example, when an undefined function is referenced in a handler, the final `.catch` will catch the resulting ReferenceError. Multiple `.then` handlers can be used with a single `.catch` to handle errors in all handlers.

When an error is caught and handled normally in a `.catch` block, control continues to the next successful `.then` handler. For instance, if an error is thrown in a promise chain, followed by a `.catch` block that handles the error and a subsequent `.then` handler, the program will continue with the next successful handler. If the error is not handled, the promise becomes rejected, and execution jumps to the closest rejection handler. In browsers, unhandled rejections result in a global error in the console, while in Node.js, they trigger the `unhandledrejection` event handler, which informs users and servers about unhandled errors to prevent app crashes.


## Error Handling with .catch

`.catch()` handles errors in promises by executing a callback function with the rejection reason as its argument when a promise is rejected. This method serves as a way to catch and handle rejection cases, though it's important to note that it behaves differently depending on the promise's state.

If a `.catch()` handler is attached to a promise that rejects without a handler, the rejection event is surfaced by the host environment. In browsers, this results in an "unhandledrejection" event, while Node.js users will receive notifications through the "unhandledrejection" event handler. This ensures that the application remains stable even when errors occur in promise chains.

When using `.catch()` with other methods like `Promise.resolve()`, you can see its behavior more clearly. For example, if you call `Promise.resolve().then(null, err => console.log('handled error'));`, the `console.log('handled error')` function will be executed with no arguments, demonstrating the interaction between these methods.

The `.catch()` method can be particularly useful when combined with other promise methods. Consider the following example: `fetch('https://no-such-server.blabla').then(response => response.json()).catch(err => alert(err))`. This structure ensures that any network or parsing errors are handled uniformly, while allowing the rest of the promise chain to continue processing successful responses.

In terms of implementation details, `.catch()` effectively serves as a wrapper for the `Promise.prototype.then` method, using the following signature: `Promise.prototype.catch(onRejected)`. When called, it internally performs `obj.then(undefined, onRejected)`, returning a new promise that adopts the final state of the original promise. This mechanism ensures consistent error handling across modern JavaScript environments while maintaining compatibility with legacy implementations.


## Chaining with .catch

The .catch() method returns a Promise that remains in the pending state, even if the previous promise is fulfilled, rejected, or still pending. This behavior allows for further chaining of promises while maintaining proper error handling. When called on a promise that is already resolved, it logs the error message but does not call the error handler.

<p>The returned promise is always pending when .catch() is called, regardless of the current promise's status. If the current promise fulfills, the .catch() method does not call the rejection handler and the returned promise fulfills with the same value. This behavior is consistent with the promise prototype's .catch method, which always returns a promise, regardless of the original promise's state.</p>

<p>When using .catch() with other methods like Promise.resolve(), you can observe its behavior more clearly. For example, calling Promise.resolve().then(null, err => console.log('handled error')) executes the console.log('handled error') function with no arguments, demonstrating the interaction between these methods.</p>

<p>The .catch() method maintains consistent error handling across modern JavaScript environments while preserving compatibility with legacy implementations. It internally calls obj.then(undefined, onRejected), returning a new promise that adopts the final state of the original promise.</p>


## Comparison with .then

The catch() method behaves similarly to the then method, with the key difference being that it requires a rejection handler function as its parameter. This means that while both methods return a new promise, catch() specifically focuses on error handling, while then() provides a more general way to handle both success and failure cases.

<p>Unlike the then method, which requires both resolve and reject handlers, catch() only takes a single argument - the rejection handler function. This design choice makes it particularly useful for error handling, as it allows developers to focus specifically on cases where a promise is rejected, without having to write additional logic for fulfilled promises.</p>

<p>When a promise is resolved, the catch method does not call the rejection handler and returns undefined. This behavior is consistent with the promise prototype's catch method, which always returns a promise, regardless of the original promise's state.</p>

<p>For example, consider the following code snippet:</p>

<pre><code>const somePromiseWithCatch = Promise.resolve(5)

  .catch(error => console.log(error));

console.log(somePromiseWithCatch); // prints "undefined"

</code></pre>

<p>In this case, since Promise.resolve(5) immediately resolves to 5 without throwing an error, the catch method doesn't log anything to the console and returns undefined.</p>

<p>When using catch() with other methods like Promise.resolve(), you can observe its behavior more clearly. For example, calling <code>Promise.resolve().then(null, err => console.log('handled error'))</code> executes the console.log('handled error') function with no arguments, demonstrating the interaction between these methods.</p>

<p>While catch() provides a convenient way to handle errors, its behavior can sometimes lead to unexpected results. For instance, if you chain multiple promises using catch(), the final catch handler may never be triggered if all previous promises resolve successfully. This is demonstrated in the following code:</p>

<pre><code>Promise.resolve('success')

  .then(value => value.toUpperCase())

  .then(value => {

    throw new Error('Something went wrong');

  })

  .catch(error => console.log(error)); // never reached

</code></pre>

<p>In this example, the final catch handler is not executed because all preceding promises resolve successfully. This behavior is consistent with the promise prototype's catch method, which always returns a promise, regardless of the original promise's state.</p>


## Browser Support

The .catch() method, which allows for error handling in JavaScript promises, gained broader support across modern browsers in June 2017, though initial support started in different versions for specific browsers: Chrome 51, Edge 15, Firefox 54, Safari 10, and Opera 38. Notably, Internet Explorer does not support this method.

The method's implementation closely mirrors that of the promise prototype's .catch method, which always returns a promise, regardless of the original promise's state. When .catch() is called on an already resolved promise, it logs the error message but does not call the error handler, demonstrating its consistent behavior across different promise states.

Key aspects of .catch()'s functionality include its ability to handle errors of all kinds - both explicit rejections and accidental errors in handlers above. This comprehensive error capturing makes it particularly useful for maintaining stable applications, even when errors occur in promise chains.

Development best practices recommend analyzing errors using custom error classes for better handling, while noting that it's acceptable not to use .catch() if recovery from an error is impossible. Modern JavaScript environments provide robust mechanisms for error management, including alternative approaches for non-browser environments like Node.js, where unhandled errors trigger specific event handlers to inform users and servers about potential application crashes.

